Workbook

Sheet Passo a Passo
A3: 1 | B3: Atualizar a aba de "Resultado" com dados extraídos do sistema ER System, de acordo com esse relatório:
A4: 2. | B4: Realizar o procedimento descrito no passo 1 acima, para todas as empresas
A17: 2 | B17: Atualizar a aba "Realizado" com os dados de resultado por produto, carteira de crédito, carteira de captação e dados de depreciação/amortização presentes na aba "TD_P&L (Total)" do check contábil
A18: 3 | B18: Atualizar a aba orçamento somente quando tiver outro orçamento vigente, nesse casos copia e cola o orçamento passado e faz o vínculo com o novo
A19: 4 | B19: Atualizar as abas "P&L Mensal" e "P&L Acumulado" com as datas do mês em análise
A20: 5 | B20: Análise das receitas operacionais: os arquivos de receita diária da contabilidade servem como base para identificar possiveis erros de roteiro, ou indicativo de outros problemas sistemicos
A21: 5.1 | B21: Os arquivos diários da contabilidade estão nos seguintes diretórios:
B22: G:\Drives compartilhados\Area - Contabilidade 2 Temp\02. CONCILIAÇÃO\1. BANCO BARI\RESULTADO\RECEITA\2025
B23: G:\Drives compartilhados\Area - Contabilidade 2\Contabilidade\05. FECHAMENTO CONTABIL\02. CONCILIAÇÃO\4. BARI CIA HIPOTECARIA\RESULTADO\2025
A24: 5.1.1 | B24: Analisar se há dias em que tem mais ou menos receitas de juros e correção monetária.
B25: Alguns pontos para relembrar:
B26: A taxa bonificada esta roteirizada para reduzir a correção monetária, o que pode levar até mesmo a negativação das receitas, principalemnte nos maiores venciemntos: 12, 18 e 20.
B27: As receitas são cálculadas em dias corridos e apropriadas em dias úteis, por isso na segunda há descarrego das receitas. Quando o fechamento do mês cai final de semana a apropriação é antecipada para sexta.
B28: A Sicred calcula em 365 os juros e o Prognum em 360. Por tanto, a forma que é apropriada gera distorção em relação ao orçado, conforme o quadro abaixo:
B30: Ano 365 dias | G30: Ano 366 dias (bissexto)
B31: Mês | C31: Qt. Dias | D31: Dias corridos | E31: Diferença de dias orçado x realizado | G31: Mês | H31: Qt. Dias | I31: Dias corridos | J31: Diferença de dias orçado x realizado
B32: janeiro | C32: 30 | D32: 31 | E32: =C32-D32 -> -1 | G32: janeiro | H32: 30 | I32: 31 | J32: =H32-I32 -> -1
B33: fevereiro | C33: 27 | D33: 28 | E33: =C33-D33 -> -1 | G33: fevereiro | H33: 28 | I33: 29 | J33: =H33-I33 -> -1
B34: março | C34: 33 | D34: 31 | E34: =C34-D34 -> 2 | G34: março | H34: 32 | I34: 31 | J34: =H34-I34 -> 1
B35: abril | C35: 29 | D35: 30 | E35: =C35-D35 -> -1 | G35: abril | H35: 29 | I35: 30 | J35: =H35-I35 -> -1
B36: maio | C36: 31 | D36: 31 | E36: =C36-D36 -> 0 | G36: maio | H36: 31 | I36: 31 | J36: =H36-I36 -> 0
B37: junho | C37: 29 | D37: 30 | E37: =C37-D37 -> -1 | G37: junho | H37: 29 | I37: 30 | J37: =H37-I37 -> -1
B38: julho | C38: 31 | D38: 31 | E38: =C38-D38 -> 0 | G38: julho | H38: 31 | I38: 31 | J38: =H38-I38 -> 0
B39: agosto | C39: 30 | D39: 31 | E39: =C39-D39 -> -1 | G39: agosto | H39: 30 | I39: 31 | J39: =H39-I39 -> -1
B40: setembro | C40: 29 | D40: 30 | E40: =C40-D40 -> -1 | G40: setembro | H40: 29 | I40: 30 | J40: =H40-I40 -> -1
B41: outubro | C41: 31 | D41: 31 | E41: =C41-D41 -> 0 | G41: outubro | H41: 31 | I41: 31 | J41: =H41-I41 -> 0
B42: novembro | C42: 29 | D42: 30 | E42: =C42-D42 -> -1 | G42: novembro | H42: 29 | I42: 30 | J42: =H42-I42 -> -1
B43: dezembro | C43: 31 | D43: 31 | E43: =C43-D43 -> 0 | G43: dezembro | H43: 31 | I43: 31 | J43: =H43-I43 -> 0
B44: Total | C44: 360 | D44: =SUM(D32:D43) -> 365 | E44: =SUM(E32:E43) -> -5 | G44: Total | H44: 360 | I44: =SUM(I32:I43) -> 366 | J44: =SUM(J32:J43) -> -6
A46: 5.1.1.1 | B46: Se precisar investigar melhor os contratos de forma análitica:
B48: Gerar Voucher p/todas as contas e verificar a descrição do movimento
B65: Gera o "Analitico por Lançamento" para verificar o evento se estiver concentrado em um único contrato, analisar para entender

Sheet Premissas
B2: Receita Externa Cebraco:
B3: Apresenta todas as receitas, exceto receita das ligadas: Banco e Hipo. Desconsidera Securitizadora, pois os valores são pagos em patrimônio separado, ou seja, a sec apenas faz a intermediação.
B4: Conta "7.1.7.99.00.000007", "RENDAS CALL CENTER (PESSOA FISICA)" do Balancete e do arquivo de Resultados da Contabilidade
B6: Receita de Serviços, Interchange e Comissão CRI
B7: Serviços >> Grupo 7.1.7 do cosif do Banco, da Hipotecária, da DI (conta cosif: 7.1.7.00.00), receita de despachante da Service (conta cosif: 7.1.7.80.00.000024) e receita Call Center da Poio (conta cosif: 7.1.7.80.00.000002) . No arquivo de "Receitas e Despesas Contabilidade", salvo no diretório "G:\Drives compartilhados\Area - FPA\FPA\29. Checks Contabilidade\2025" há toda a relação dos "de-paras" nas abas do BANCO e da HIPO.
B8: A conta cosif "7.1.7.99.00.00.000013 - COORDENADOR LÍDER", é alocada em Receita de CRI
B9: As contas cosif "7.1.7.99.00.00.000015 - RECEITA INTERCHANGE - FUNCAO CREDITO", "7.1.7.99.00.00.000016 - RECEITA INTERCHANGE - FUNCAO DEBITO" e "7.1.7.99.00.00.000017 - BOLETO DE DEPOSITO LIQUIDADO" são alocada em Receita de Interchange. A divisão entre Consignado e Imobiliário é feita da seguinte forma: 42,6% para Consignado e 57,4% para Imobiliário.
B11: Receita cobrança externa Cebraco
B12: Receitas de prestação de serviços das empresas terceiras.
B13: Valor extraído da planilha "TD_P&L (Total)" do check contábil, célula "D12"
B14: Esse valor deve coincidir com a soma das contas cosif (7.1.7.99.00.000005 e 7.1.7.99.00.000007) do balancete da Cebraco
B16: Resultado de Seguros
... B77: 2) As demais rúbricas contábeis do cartão são alocadas da seguinte forma: 1) 42,6% para o Consignado e 57,4% para o Imobiliário.
A79: Não estamos utilizando os critérios específicados dessa linha para baixo
B81: PART. CONTROLADAS (SEC)
B82: 1) O dados é o mesmo que está na planilha "RESULTADO" e correspondente ao lucro líquido da Sec
B84: Critério de Rateio Captação:
B85: Lógica até Abril/2023
B86: Cartão é o resultado da receita de float/despesa da carteira de crédito que gera juros (desconsidera Creliq).
B87: Imobiliário --> LCI + CDB/LC - IPCA e IGPM + Resultado de Swap.
B88: Consignado --> CDB/LC - Pré/DI
B89: Outros (Receita Financeira, FGC, DPGE, e LFS) --> rateado pela carteira de consignado e imobiliário.
B90: Lógica após Maio/2023
B91: Cartão é o resultado da receita de float/despesa da carteira de crédito.
B92: Consignado --> Consome a despesa até fechar a carteira de ativa e passiva, na seguinte ordem quanto faltar carteira: CDB/LC - Pré, CDB/LC - DI, LCI - Pré e LCI - DI e Resultado Swap (DI x Pré)
B93: Imobiliário --> LCI + CDB/LC - IPCA e IGPM + Resultado de Swap (DI x IPCA), e o restante LCI Pré e DI que não forem utilizadas para fechar a carteira do consignado.
... B108: A partir de julho/24: versão de Março/24 adequando os rateios para retirada do banco digital.

Sheet RESULTADO
B2: Mês | C2: =EOMONTH(D2,-1) -> 44926 | D2: 44957 | E2: 44985 | F2: 45016 | G2: 1º TRIM | I2: =EOMONTH(F2:F2,1) -> 45046 | J2: =EOMONTH(I2:I2,1) -> 45077 | K2: =EOMONTH(J2:J2,1) -> 45107 | M2: 2º TRIM | O2: 1º SEM | Q2: =EOMONTH(K2,1) -> 45138 | R2: =EOMONTH(Q2:Q2,1) -> 45169 | S2: =EOMONTH(R2:R2,1) -> 45199 | U2: 3º TRIM | W2: =EOMONTH(S2:S2,1) -> 45230 | X2: 45260 | Y2: =EOMONTH(X2:X2,1) -> 45291 | AA2: 4º TRIM | AC2: 2º SEM | AE2: 2023 | AG2: 45322 | AH2: =EOMONTH(AG2,1) -> 45351 | AI2: =EOMONTH(AH2,1) -> 45382 | AK2: 1º TRIM | AM2: =EOMONTH(AI2:AI2,1) -> 45412 | AN2: =EOMONTH(AM2:AM2,1) -> 45443 | AO2: =EOMONTH(AN2:AN2,1) -> 45473 | AQ2: 2º TRIM | AS2: 1º SEM | AU2: =EOMONTH(AO2,1) -> 45504 | AV2: =EOMONTH(AU2:AU2,1) -> 45535 | AW2: =EOMONTH(AV2:AV2,1) -> 45565 | AY2: 3º TRIM | BA2: =EOMONTH(AW2:AW2,1) -> 45596 | BB2: =EOMONTH(BA2:BA2,1) -> 45626 | BC2: =EOMONTH(BB2:BB2,1) -> 45657 | BE2: 4º TRIM | BG2: 2º SEM | BI2: 2024 | BJ2: =EOMONTH(BC2,1) -> 45688 | BK2: =EOMONTH(BJ2,1) -> 45716 | BL2: =EOMONTH(BK2,1) -> 45747 | BM2: =EOMONTH(BL2:BL2,1) -> 45777 | BN2: =EOMONTH(BM2:BM2,1) -> 45808 | BO2: =EOMONTH(BN2:BN2,1) -> 45838 | BP2: =EOMONTH(BO2,1) -> 45869 | BQ2: =EOMONTH(BP2:BP2,1) -> 45900 | BR2: 45930 | BS2: =EOMONTH(BR2:BR2,1) -> 45961 | BT2: =EOMONTH(BS2,1) -> 45991 | BU2: =EOMONTH(BT2,1) -> 46022 | BW2: 4º TRIM | BY2: 2º SEM | CA2: YTD | CC2: =EOMONTH(BU2,1) -> 46053 | CD2: =EOMONTH(CC2,1) -> 46081 | CE2: =EOMONTH(CD2,1) -> 46112
B3: Banco | C3: -1225882.7 | D3: -2256281.8 | E3: -551555.87 | F3: 6437130.8 | G3: =SUM(D3:F3) -> 3629293.1 | I3: -1840435.7 | J3: 471919.39 | K3: 2444762.5 | M3: =SUM(I3:K3) -> 1076246.2 | O3: =SUM(I3:K3,D3:F3) -> 4705539.4 | Q3: -13238.56 | R3: -260697.35 | S3: 5983559.6 | U3: =SUM(Q3:S3) -> 5709623.7 | W3: 2301934.6 | X3: 2390376.4 | Y3: 7139953.1 | AA3: =SUM(W3:Y3) -> 11832264 | AC3: =SUM(W3:Y3,Q3:S3) -> 17541888 | AE3: =O3+AC3 -> 22247427 | AG3: 135333.08 | AH3: 1351348.1 | AI3: 1607493.6 | AK3: =SUM(AG3:AI3) -> 3094174.8 | AM3: 1778241.2 | AN3: 668906.43 | AO3: 4951864.8 | AQ3: =SUM(AM3:AO3) -> 7399012.4 | AS3: =SUM(AM3:AO3,AG3:AI3) -> 10493187 | AU3: 1208517.6 | AV3: 1317888.3 | AW3: 3497673 | AY3: =SUM(AU3:AW3) -> 6024078.8 | BA3: 407091.3 | BB3: 2060889.3 | BC3: 9185197.5 | BE3: =SUM(BA3:BC3) -> 11653178 | BG3: =SUM(BA3:BC3,AU3:AW3) -> 17677257 | BI3: =AS3+BG3 -> 28170444 | BJ3: 1184338 | BK3: 476737.52 | BL3: 5719093.2 | BM3: 4177224.8 | BN3: 2356700.7 | BO3: 4784053.5 | BP3: 2422631.3 | BQ3: 2180653 | BR3: 3140838.3 | BS3: 462356.73 | BT3: 3972262 | BU3: 4603577 | BW3: =SUM(BS3:BU3) -> 9038195.8 | BY3: =SUM(BS3:BU3,BP3:BR3) -> 16782318 | CA3: =SUM(BJ3:BU3) -> 35480466 | CC3: 1868086.1 | CD3: 2667098.7 | CE3: 4416073.4
B4: Equiv.Patr. | C4: 453185.32 | D4: 771628.33 | E4: 1431454.9 | F4: 2102188.9 | G4: =SUM(D4:F4) -> 4305272.2 | I4: 436785.4 | J4: 417689.25 | K4: 2852793 | M4: =SUM(I4:K4) -> 3707267.6 | O4: =SUM(I4:K4,D4:F4) -> 8012539.8 | Q4: 554506.77 | R4: 852807.67 | S4: -43758.08 | U4: =SUM(Q4:S4) -> 1363556.4 | W4: 944140.65 | X4: 1170510.6 | Y4: -2091085.1 | AA4: =SUM(W4:Y4) -> 23566.16 | AC4: =SUM(W4:Y4,Q4:S4) -> 1387122.5 | AE4: =O4+AC4 -> 9399662.3 | AG4: 172056.15 | AH4: 533427.26 | AI4: 444797.31 | AK4: =SUM(AG4:AI4) -> 1150280.7 | AM4: 485176.53 | AN4: 762992.45 | AO4: 512552.2 | AQ4: =SUM(AM4:AO4) -> 1760721.2 | AS4: =SUM(AM4:AO4,AG4:AI4) -> 2911001.9 | AU4: 754648.1 | AV4: 477878.87 | AW4: -268578.25 | AY4: =SUM(AU4:AW4) -> 963948.72 | BA4: -655785.64 | BB4: 745429.73 | BC4: 1669542.1 | BE4: =SUM(BA4:BC4) -> 1759186.2 | BG4: =SUM(BA4:BC4,AU4:AW4) -> 2723134.9 | BI4: =AS4+BG4 -> 5634136.8 | BJ4: 541079.53 | BK4: 991900.92 | BL4: 1442485.3 | BM4: 1665618.3 | BN4: 1190816.5 | BO4: 1675707.9 | BP4: 1137988.6 | BQ4: 322307.46 | BR4: 869987.47 | BS4: 382306.92 | BT4: 1854232.9 | BU4: 1765324.5 | BW4: =SUM(BS4:BU4) -> 4001864.3 | BY4: =SUM(BS4:BU4,BP4:BR4) -> 6332147.9 | CA4: =SUM(BJ4:BU4) -> 13839756 | CC4: 1404277.8 | CD4: 1441916.6 | CE4: 1955492.4
B5: JCP + Dividendos | C5: 191960.21 | D5: 0 | E5: 0 | F5: 0 | G5: =SUM(D5:F5) -> 0 | I5: 0 | J5: 0 | K5: 0 | M5: =SUM(I5:K5) -> 0 | O5: =SUM(I5:K5,D5:F5) -> 0 | Q5: 0 | R5: 0 | S5: 0 | U5: =SUM(Q5:S5) -> 0 | W5: 0 | X5: 0 | Y5: 4864009.9 | AA5: =SUM(W5:Y5) -> 4864009.9 | AC5: =SUM(W5:Y5,Q5:S5) -> 4864009.9 | AE5: =O5+AC5 -> 4864009.9 | AG5: 0 | AH5: 0 | AI5: 0 | AK5: =SUM(AG5:AI5) -> 0 | AM5: 0 | AN5: 0 | AO5: 1018230.3 | AQ5: =SUM(AM5:AO5) -> 1018230.3 | AS5: =SUM(AM5:AO5,AG5:AI5) -> 1018230.3 | AU5: 0 | AV5: 0 | AW5: 0 | AY5: =SUM(AU5:AW5) -> 0 | BA5: 0 | BB5: 0 | BC5: 683065.86 | BE5: =SUM(BA5:BC5) -> 683065.86 | BG5: =SUM(BA5:BC5,AU5:AW5) -> 683065.86 | BI5: =AS5+BG5 -> 1701296.2 | BJ5: 0 | BK5: 0 | BL5: 0 | BM5: 0 | BN5: 0 | BO5: 0 | BP5: 0 | BQ5: 0 | BR5: 0 | BS5: 0 | BT5: 0 | BU5: 0 | BW5: =SUM(BS5:BU5) -> 0 | BY5: =SUM(BS5:BU5,BP5:BR5) -> 0 | CA5: =SUM(BJ5:BU5) -> 0 | CC5: 0 | CD5: 0 | CE5: 0
B6: Resultado Banco | C6: -1871028.2 | D6: =D3-D4-D5 -> -3027910.1 | E6: =E3-E4-E5 -> -1983010.8 | F6: =F3-F4-F5 -> 4334941.8 | G6: =SUM(D6:F6) -> -675979.02 | I6: =I3-I4-I5 -> -2277221.1 | J6: =J3-J4-J5 -> 54230.14 | K6: =K3-K4-K5 -> -408030.44 | M6: =SUM(I6:K6) -> -2631021.4 | O6: =O3-O4-O5 -> -3307000.4 | Q6: =Q3-Q4-Q5 -> -567745.33 | R6: =R3-R4-R5 -> -1113505 | S6: =S3-S4-S5 -> 6027317.7 | U6: =SUM(Q6:S6) -> 4346067.3 | W6: 1357793.9 | X6: 1219865.8 | Y6: 4367028.2 | AA6: =SUM(W6:Y6) -> 6944688 | AC6: =AC3-AC4-AC5 -> 11290755 | AE6: =AE3-AE4-AE5 -> 7983754.9 | AG6: -36723.07 | AH6: 817920.86 | AI6: 1162696.3 | AK6: =SUM(AG6:AI6) -> 1943894.1 | AM6: 1293064.6 | AN6: -94086.02 | AO6: 3421082.3 | AQ6: =SUM(AM6:AO6) -> 4620060.9 | AS6: =AS3-AS4-AS5 -> 6563955 | AU6: 453869.49 | AV6: 840009.4 | AW6: 3766251.2 | AY6: =SUM(AU6:AW6) -> 5060130.1 | BA6: 1062876.9 | BB6: 1315459.6 | BC6: 6832589.5 | BE6: =SUM(BA6:BC6) -> 9210926.1 | BG6: =BG3-BG4-BG5 -> 14271056 | BI6: =BI3-BI4-BI5 -> 20835011 | BJ6: 643258.46 | BK6: -515163.4 | BL6: 4276607.9 | BM6: 2511606.5 | BN6: 1165884.2 | BO6: 3108345.6 | BP6: 1284642.7 | BQ6: 1858345.5 | BR6: 2270850.8 | BS6: 80049.81 | BT6: 2118029.2 | BU6: 2838252.5 | BW6: =SUM(BS6:BU6) -> 5036331.4 | BY6: =BY3-BY4-BY5 -> 10450170 | CA6: =SUM(BJ6:BU6) -> 21640710 | CC6: 463808.25 | CD6: 1225182.2 | CE6: =CE3-CE4 -> 2460581.1
B7: Hipotecária | C7: 569477.66 | D7: 184324.92 | E7: 1250477.1 | F7: 2071688.5 | G7: =SUM(D7:F7) -> 3506490.6 | I7: 411267.6 | J7: -80452.38 | K7: 2556900.1 | M7: =SUM(I7:K7) -> 2887715.3 | O7: =SUM(I7:K7,D7:F7) -> 6394205.9 | Q7: 370274.9 | R7: 507165.18 | S7: -90122.92 | U7: =SUM(Q7:S7) -> 787317.16 | W7: 886582.6 | X7: 857060.12 | Y7: 2345408.5 | AA7: =SUM(W7:Y7) -> 4089051.2 | AC7: =SUM(W7:Y7,Q7:S7) -> 4876368.4 | AE7: =O7+AC7 -> 11270574 | AG7: 110976.49 | AH7: 411297.69 | AI7: 236500.31 | AK7: =SUM(AG7:AI7) -> 758774.49 | AM7: 434611.59 | AN7: 404507.76 | AO7: 1338115.9 | AQ7: =SUM(AM7:AO7) -> 2177235.2 | AS7: =SUM(AM7:AO7,AG7:AI7) -> 2936009.7 | AU7: 617707.85 | AV7: 430066.94 | AW7: -305419.29 | AY7: =SUM(AU7:AW7) -> 742355.5 | BA7: -811427.31 | BB7: 850419.33 | BC7: 1712350.7 | BE7: =SUM(BA7:BC7) -> 1751342.7 | BG7: =SUM(BA7:BC7,AU7:AW7) -> 2493698.2 | BI7: =AS7+BG7 -> 5429707.9 | BJ7: 464703.12 | BK7: 871800.97 | BL7: 1249780.1 | BM7: 1592797.9 | BN7: 1100442.5 | BO7: 1636029.5 | BP7: 1078640.2 | BQ7: 108896.66 | BR7: 685150.93 | BS7: 198757.09 | BT7: 1665017.2 | BU7: 1403074.8 | BW7: =SUM(BS7:BU7) -> 3266849.1 | BY7: =SUM(BS7:BU7,BP7:BR7) -> 5139537 | CA7: =SUM(BJ7:BU7) -> 12055091 | CC7: 1359401.9 | CD7: 1158533.6 | CE7: 2104762.7
B8: Resultado Congl. Financeiro | C8: -1301550.5 | D8: -2843585.2 | E8: -732533.64 | F8: 6406630.4 | G8: =SUM(D8:F8) -> 2830511.5 | I8: -1865953.5 | J8: -26222.24 | K8: 2148869.7 | M8: =SUM(I8:K8) -> 256693.93 | O8: =SUM(I8:K8,D8:F8) -> 3087205.5 | Q8: -197470.43 | R8: -606339.84 | S8: 5937194.8 | U8: =SUM(Q8:S8) -> 5133384.5 | W8: 2244376.5 | X8: 2076926 | Y8: 6712436.7 | AA8: =SUM(W8:Y8) -> 11033739 | AC8: =SUM(W8:Y8,Q8:S8) -> 16167124 | AE8: =O8+AC8 -> 19254329 | AG8: 74253.42 | AH8: 1229218.5 | AI8: 1399196.6 | AK8: =SUM(AG8:AI8) -> 2702668.6 | AM8: 1727676.2 | AN8: 310421.74 | AO8: 4759198.2 | AQ8: =SUM(AM8:AO8) -> 6797296.1 | AS8: =SUM(AM8:AO8,AG8:AI8) -> 9499964.7 | AU8: 1071577.3 | AV8: 1270076.3 | AW8: 3460831.9 | AY8: =SUM(AU8:AW8) -> 5802485.6 | BA8: 251449.63 | BB8: 2165878.9 | BC8: 8544940.2 | BE8: =SUM(BA8:BC8) -> 10962269 | BG8: =SUM(BA8:BC8,AU8:AW8) -> 16764754 | BI8: =AS8+BG8 -> 26264719 | BJ8: =SUM(BJ6:BJ7) -> 1107961.6 | BK8: =SUM(BK6:BK7) -> 356637.57 | BL8: =SUM(BL6:BL7) -> 5526388 | BM8: =SUM(BM6:BM7) -> 4104404.4 | BN8: =SUM(BN6:BN7) -> 2266326.7 | BO8: =SUM(BO6:BO7) -> 4744375.1 | BP8: =SUM(BP6:BP7) -> 2363282.9 | BQ8: =SUM(BQ6:BQ7) -> 1967242.2 | ... BU8: =SUM(BU6:BU7) -> 4241327.3 | BW8: =SUM(BS8:BU8) -> 8303180.6 | BY8: =SUM(BS8:BU8,BP8:BR8) -> 15589707 | CA8: =SUM(CA6:CA7) -> 33695801 | CC8: =CC6+CC7 -> 1823210.1 | CD8: =CD6+CD7 -> 2383715.7 | CE8: =CE6+CE7 -> 4565343.7
B10: Apoio | C10: 3097.06 | D10: 45761.36 | E10: 41357.84 | F10: 179237.57 | G10: =SUM(D10:F10) -> 266356.77 | I10: -41623.05 | J10: 187462.07 | K10: -169417.16 | M10: =SUM(I10:K10) -> -23578.14 | O10: =SUM(I10:K10,D10:F10) -> 242778.63 | Q10: 63133.63 | R10: -208725.83 | S10: -304926.61 | U10: =SUM(Q10:S10) -> -450518.81 | W10: 64962.49 | X10: -408320.5 | Y10: -388305.66 | AA10: =SUM(W10:Y10) -> -731663.67 | AC10: =SUM(W10:Y10,Q10:S10) -> -1182182.5 | AE10: =O10+AC10 -> -939403.85 | AG10: 97102.96 | AH10: 301216.36 | AI10: -88491.62 | AK10: =SUM(AG10:AI10) -> 309827.7 | AM10: 113308.82 | AN10: 67062.17 | AO10: -111222.36 | AQ10: =SUM(AM10:AO10) -> 69148.63 | AS10: =SUM(AM10:AO10,AG10:AI10) -> 378976.33 | AU10: 103829.47 | AV10: -140484.96 | AW10: 170123.99 | AY10: =SUM(AU10:AW10) -> 133468.5 | BA10: -220088.02 | BB10: 900.53 | BC10: 94783.98 | BE10: =SUM(BA10:BC10) -> -124403.51 | BG10: =SUM(BA10:BC10,AU10:AW10) -> 9064.99 | BI10: =AS10+BG10 -> 388041.32 | BJ10: 8662.4 | BK10: -46398.02 | BL10: -198223.76 | BM10: 286595.95 | BN10: 250051.98 | BO10: 454587.93 | BP10: 531355.39 | BQ10: 457762.47 | BR10: 267242.22 | BS10: 668876.32 | BT10: 368998.71 | BU10: -137032.85 | BW10: =SUM(BS10:BU10) -> 900842.18 | BY10: =SUM(BS10:BU10,BP10:BR10) -> 2157202.3 | CA10: =SUM(BJ10:BL10)+SUM(BM10:BO10)+SUM(BP10:BR10)+SUM(BS10:BU10) -> 2912478.7 | CC10: -67205.14 | CD10: 307562.98 | CE10: 558365.81
B11: Service | C11: -682901.3 | D11: 992683.36 | E11: -497496.4 | F11: 560056.26 | G11: =SUM(D11:F11) -> 1055243.2 | I11: 50070 | J11: 52449.68 | K11: -58278.43 | M11: =SUM(I11:K11) -> 44241.25 | O11: =SUM(I11:K11,D11:F11) -> 1099484.5 | Q11: -107595.78 | R11: -143340.37 | S11: -49664.58 | U11: =SUM(Q11:S11) -> -300600.73 | W11: -83197.01 | X11: -191600.36 | Y11: -144210.21 | AA11: =SUM(W11:Y11) -> -419007.58 | AC11: =SUM(W11:Y11,Q11:S11) -> -719608.31 | AE11: =O11+AC11 -> 379876.16 | AG11: -132549.64 | AH11: -53812.19 | AI11: -164625.97 | AK11: =SUM(AG11:AI11) -> -350987.8 | AM11: -198315.59 | AN11: -50199.64 | AO11: 12376.66 | AQ11: =SUM(AM11:AO11) -> -236138.57 | AS11: =SUM(AM11:AO11,AG11:AI11) -> -587126.37 | AU11: -117486.72 | AV11: -47222 | AW11: 7254.56 | AY11: =SUM(AU11:AW11) -> -157454.16 | BA11: -74550.02 | BB11: -39497.45 | BC11: 46645.51 | BE11: =SUM(BA11:BC11) -> -67401.96 | BG11: =SUM(BA11:BC11,AU11:AW11) -> -224856.12 | BI11: =AS11+BG11 -> -811982.49 | BJ11: 21886.98 | BK11: -131785.62 | BL11: 92197.89 | BM11: 39268.28 | BN11: 324440.4 | BO11: 182046.23 | BP11: 167219.5 | BQ11: 129182.02 | BR11: 203916.29 | BS11: 245380.69 | BT11: 172928.84 | BU11: 212227.37 | BW11: =SUM(BS11:BU11) -> 630536.9 | BY11: =SUM(BS11:BU11,BP11:BR11) -> 1130854.7 | CA11: =SUM(BJ11:BL11)+SUM(BM11:BO11)+SUM(BP11:BR11)+SUM(BS11:BU11) -> 1658908.9 | CC11: 336620.5 | CD11: 238788.3 | CE11: 348085
B12: Sec | C12: -117389.37 | D12: 403864.17 | E12: 37532.65 | F12: 35087.87 | G12: =SUM(D12:F12) -> 476484.69 | I12: 20981.69 | J12: 302749.95 | K12: 24903.45 | M12: =SUM(I12:K12) -> 348635.09 | O12: =SUM(I12:K12,D12:F12) -> 825119.78 | Q12: 22459.15 | R12: 373949.41 | S12: 92606.79 | U12: =SUM(Q12:S12) -> 489015.35 | W12: 96234.81 | X12: 284203.71 | Y12: 192942.88 | AA12: =SUM(W12:Y12) -> 573381.4 | AC12: =SUM(W12:Y12,Q12:S12) -> 1062396.8 | AE12: =O12+AC12 -> 1887516.5 | AG12: 93813.74 | AH12: 135265.85 | AI12: 219542.37 | AK12: =SUM(AG12:AI12) -> 448621.96 | AM12: 114837.02 | AN12: 356560.25 | AO12: 208072.75 | AQ12: =SUM(AM12:AO12) -> 679470.02 | AS12: =SUM(AM12:AO12,AG12:AI12) -> 1128092 | AU12: 123558.82 | AV12: 40796.91 | AW12: 65236.66 | AY12: =SUM(AU12:AW12) -> 229592.39 | BA12: 171614.12 | BB12: -77824.7 | BC12: 584288.66 | BE12: =SUM(BA12:BC12) -> 678078.08 | BG12: =SUM(BA12:BC12,AU12:AW12) -> 907670.47 | BI12: =AS12+BG12 -> 2035762.5 | BJ12: 55268.02 | BK12: 91252.77 | BL12: 263356.18 | BM12: 62767.15 | BN12: 98598.14 | BO12: 54470.74 | BP12: 91139.91 | BQ12: 214580.78 | BR12: 198117.49 | BS12: 178204.25 | BT12: 188001.86 | BU12: 387325.03 | BW12: =SUM(BS12:BU12) -> 753531.14 | BY12: =SUM(BS12:BU12,BP12:BR12) -> 1257369.3 | CA12: =SUM(BJ12:BL12)+SUM(BM12:BO12)+SUM(BP12:BR12)+SUM(BS12:BU12) -> 1883082.3 | CC12: 56226.37 | CD12: 243037.75 | CE12: 521291.11
B13: Cebraco | C13: 156241.1 | D13: 251871.21 | E13: 45403.03 | F13: 327936.67 | G13: =SUM(D13:F13) -> 625210.91 | I13: 138298.78 | J13: 144880.25 | K13: 186119.58 | M13: =SUM(I13:K13) -> 469298.61 | O13: =SUM(I13:K13,D13:F13) -> 1094509.5 | Q13: 141568.1 | R13: 89515.94 | S13: 134228.26 | U13: =SUM(Q13:S13) -> 365312.3 | W13: 216658.5 | X13: 190560.57 | Y13: 195389.68 | AA13: =SUM(W13:Y13) -> 602608.75 | AC13: =SUM(W13:Y13,Q13:S13) -> 967921.05 | AE13: =O13+AC13 -> 2062430.6 | AG13: 281362.26 | AH13: 228173.23 | AI13: 367935.48 | AK13: =SUM(AG13:AI13) -> 877470.97 | AM13: 416560.49 | AN13: 493559.89 | AO13: 254753.61 | AQ13: =SUM(AM13:AO13) -> 1164874 | AS13: =SUM(AM13:AO13,AG13:AI13) -> 2042345 | AU13: 414080.85 | AV13: 435825.79 | AW13: 431763.56 | AY13: =SUM(AU13:AW13) -> 1281670.2 | BA13: 305013.57 | BB13: 298153 | BC13: 244333.2 | BE13: =SUM(BA13:BC13) -> 847499.77 | BG13: =SUM(BA13:BC13,AU13:AW13) -> 2129170 | BI13: =AS13+BG13 -> 4171514.9 | BJ13: 383753.36 | BK13: 247766.94 | BL13: 197344.81 | BM13: 348062.45 | BN13: 323628.41 | BO13: 296101.84 | BP13: 214279.3 | BQ13: 295074.06 | BR13: 255574.77 | BS13: 270061.93 | BT13: 196618.29 | BU13: 334510.67 | BW13: =SUM(BS13:BU13) -> 801190.89 | BY13: =SUM(BS13:BU13,BP13:BR13) -> 1566119 | CA13: =SUM(BJ13:BL13)+SUM(BM13:BO13)+SUM(BP13:BR13)+SUM(BS13:BU13) -> 3362776.8 | CC13: 294487.17 | CD13: 193404.44 | CE13: 504122.76
B14: Marumbi | C14: -10022.49 | D14: 6101.14 | E14: 5599.87 | F14: 8798.99 | G14: =SUM(D14:F14) -> 20500 | I14: 7479.12 | J14: 9028.82 | K14: 91166.22 | M14: =SUM(I14:K14) -> 107674.16 | O14: =SUM(I14:K14,D14:F14) -> 128174.16 | Q14: -80984.46 | R14: 6475.46 | S14: -102983.23 | U14: =SUM(Q14:S14) -> -177492.23 | W14: 5833.58 | X14: 5190.32 | Y14: 4246.43 | AA14: =SUM(W14:Y14) -> 15270.33 | AC14: =SUM(W14:Y14,Q14:S14) -> -162221.9 | AE14: =O14+AC14 -> -34047.74 | AG14: 4972.24 | AH14: 4496.2 | AI14: -90847.58 | AK14: =SUM(AG14:AI14) -> -81379.14 | AM14: 4208.76 | AN14: 328.11 | AO14: 2786.93 | AQ14: =SUM(AM14:AO14) -> 7323.8 | AS14: =SUM(AM14:AO14,AG14:AI14) -> -74055.34 | AU14: -74768.8 | AV14: -131095.45 | AW14: 3837.14 | AY14: =SUM(AU14:AW14) -> -202027.11 | BA14: -100170.1 | BB14: -1819.17 | BC14: -2292.54 | BE14: =SUM(BA14:BC14) -> -104281.81 | BG14: =SUM(BA14:BC14,AU14:AW14) -> -306308.92 | BI14: =AS14+BG14 -> -380364.26 | BJ14: -2520.6 | BK14: -3154.34 | BL14: -2221.54 | BM14: -1911.07 | BN14: -1765.32 | BO14: -13358.99 | BP14: -12817.43 | BQ14: -13598.6 | BR14: -13542.27 | BS14: -13644.72 | BT14: -15611.28 | BU14: -14857.27 | BW14: =SUM(BS14:BU14) -> -44113.27 | BY14: =SUM(BS14:BU14,BP14:BR14) -> -84071.57 | CA14: =SUM(BJ14:BL14)+SUM(BM14:BO14)+SUM(BP14:BR14)+SUM(BS14:BU14) -> -109003.43 | CC14: -17113.78 | CD14: -14676.51 | CE14: -115574.2
B15: Tec | C15: -791480.18 | D15: 731451.37 | E15: -308631 | F15: 199923.47 | G15: =SUM(D15:F15) -> 622743.84 | I15: -21687.43 | J15: 10700.66 | K15: -2039.33 | M15: =SUM(I15:K15) -> -13026.1 | O15: =SUM(I15:K15,D15:F15) -> 609717.74 | Q15: -20611.62 | R15: 3981.71 | S15: 13111.09 | U15: =SUM(Q15:S15) -> -3518.82 | W15: -79586.88 | X15: -148771.42 | Y15: -71492.45 | AA15: =SUM(W15:Y15) -> -299850.75 | AC15: =SUM(W15:Y15,Q15:S15) -> -303369.57 | AE15: =O15+AC15 -> 306348.17 | AG15: -26043.14 | AH15: 8362.07 | AI15: 168585.77 | AK15: =SUM(AG15:AI15) -> 150904.7 | AM15: -24037.35 | AN15: -16277.97 | AO15: 1932.08 | AQ15: =SUM(AM15:AO15) -> -38383.24 | AS15: =SUM(AM15:AO15,AG15:AI15) -> 112521.46 | AU15: 45009.27 | AV15: -19884.46 | AW15: -1861.78 | AY15: =SUM(AU15:AW15) -> 23263.03 | BA15: -67172.13 | BB15: -2038.33 | BC15: -6070.28 | BE15: =SUM(BA15:BC15) -> -75280.74 | BG15: =SUM(BA15:BC15,AU15:AW15) -> -52017.71 | BI15: =AS15+BG15 -> 60503.75 | BJ15: -40549.83 | BK15: -34014.34 | BL15: 2298.89 | BM15: 253236.47 | BN15: -91675.21 | BO15: -113088.48 | BP15: -139859.02 | BQ15: -10120.06 | BR15: -59334.21 | BS15: 186513.9 | BT15: -75603.34 | BU15: 32313.39 | BW15: =SUM(BS15:BU15) -> 143223.95 | BY15: =SUM(BS15:BU15,BP15:BR15) -> -66089.34 | CA15: =SUM(BJ15:BU15) -> -89881.84 | CC15: 6528.27 | CD15: -37526.59 | CE15: 76283.56
B16: Bariseg | C16: 384459.99 | D16: 392200.68 | E16: 398056.12 | F16: 375279.68 | G16: =SUM(D16:F16) -> 1165536.5 | I16: -14816.54 | J16: -10399 | K16: -2698.56 | M16: =SUM(I16:K16) -> -27914.1 | O16: =SUM(I16:K16,D16:F16) -> 1137622.4 | Q16: -1222.42 | R16: 13842.24 | S16: 56539.34 | U16: =SUM(Q16:S16) -> 69159.16 | W16: 31595.86 | X16: 25703.99 | Y16: -205781.68 | AA16: =SUM(W16:Y16) -> -148481.83 | AC16: =SUM(W16:Y16,Q16:S16) -> -79322.67 | AE16: =O16+AC16 -> 1058299.7 | AG16: 57666.95 | AH16: 27904.34 | AI16: 66053.48 | AK16: =SUM(AG16:AI16) -> 151624.77 | AM16: 89488.39 | AN16: 112473.42 | AO16: 112826.47 | AQ16: =SUM(AM16:AO16) -> 314788.28 | AS16: =SUM(AM16:AO16,AG16:AI16) -> 466413.05 | AU16: 105280.44 | AV16: 143270.29 | AW16: 159460.57 | AY16: =SUM(AU16:AW16) -> 408011.3 | BA16: 151077.13 | BB16: 187338.62 | BC16: 197245.09 | BE16: =SUM(BA16:BC16) -> 535660.84 | BG16: =SUM(BA16:BC16,AU16:AW16) -> 943672.14 | BI16: =AS16+BG16 -> 1410085.2 | BJ16: 207239.06 | BK16: 195013.08 | BL16: 144849.37 | BM16: 714727.3 | BN16: 777002.52 | BO16: 744540.08 | BP16: 672727.21 | BQ16: 726660.72 | BR16: 786885.56 | BS16: 1080237.8 | BT16: 791082.68 | BU16: 885803.25 | BW16: =SUM(BS16:BU16) -> 2757123.8 | BY16: =SUM(BS16:BU16,BP16:BR16) -> 4943397.3 | CA16: =SUM(BJ16:BU16) -> 7726768.7 | CC16: 828615.88 | CD16: 743112.13 | CE16: 853652.17
B17: DI | C17: 109356.42 | D17: 301296.69 | E17: 139257.8 | F17: 232489.41 | G17: =SUM(D17:F17) -> 673043.9 | I17: 263989.08 | J17: 49350.59 | K17: 39650.02 | M17: =SUM(I17:K17) -> 352989.69 | O17: =SUM(I17:K17,D17:F17) -> 1026033.6 | Q17: 112270.02 | R17: 124876.76 | S17: 45239.83 | U17: =SUM(Q17:S17) -> 282386.61 | W17: 134299.5 | X17: 83571.06 | Y17: 57294.26 | AA17: =SUM(W17:Y17) -> 275164.82 | AC17: =SUM(W17:Y17,Q17:S17) -> 557551.43 | AE17: =O17+AC17 -> 1583585 | AG17: 466252.26 | AH17: 248335.25 | AI17: 203476.8 | AK17: =SUM(AG17:AI17) -> 918064.31 | AM17: 282459.26 | AN17: 245432.29 | AO17: 206602.16 | AQ17: =SUM(AM17:AO17) -> 734493.71 | AS17: =SUM(AM17:AO17,AG17:AI17) -> 1652558 | AU17: 270758.64 | AV17: 266385.47 | AW17: 271784.93 | AY17: =SUM(AU17:AW17) -> 808929.04 | BA17: 249579.28 | BB17: 275812.11 | BC17: 211510.14 | BE17: =SUM(BA17:BC17) -> 736901.53 | BG17: =SUM(BA17:BC17,AU17:AW17) -> 1545830.6 | BI17: =AS17+BG17 -> 3198388.6 | BJ17: 240407.82 | BK17: 411839.17 | BL17: 279665.81 | BM17: 373531.63 | BN17: 295129.34 | BO17: 298405.16 | BP17: 423635.39 | BQ17: 406830.35 | BR17: 414584.86 | BS17: 503719.17 | BT17: 349160.14 | BU17: 326824.55 | BW17: =SUM(BS17:BU17) -> 1179703.9 | BY17: =SUM(BS17:BU17,BP17:BR17) -> 2424754.5 | CA17: =SUM(BJ17:BU17) -> 4323733.4 | CC17: 397092.06 | CD17: 252933.85 | CE17: 478274.25
B18: Bari Capital | BJ18: 25293.19 | BK18: 19767.84 | BL18: 20060.59 | BM18: 30800.68 | BN18: 15422.58 | BO18: 26663.53 | BP18: 51975.09 | BQ18: 44285.86 | BR18: 86107.31 | BS18: 79295.22 | BT18: 68143.26 | BU18: 77136.36 | BW18: =SUM(BS18:BU18) -> 224574.84 | BY18: =SUM(BS18:BU18,BP18:BR18) -> 406943.1 | CA18: =SUM(BJ18:BU18) -> 544951.51 | CC18: 113327.59 | CD18: -629.72 | CE18: -202789.07
B19: Resultado Coligadas | C19: -647967.51 | D19: 3413438.7 | E19: 76555.93 | F19: 1854471.9 | G19: =SUM(D19:F19) -> 5344466.5 | I19: 947786.42 | J19: 1044795.3 | K19: 383120.09 | M19: =SUM(I19:K19) -> 2375701.8 | O19: =SUM(I19:K19,D19:F19) -> 7720168.3 | Q19: 370689.56 | R19: 260575.32 | S19: -115849.11 | U19: =SUM(Q19:S19) -> 515415.77 | W19: 386800.85 | X19: -159462.63 | Y19: -359916.75 | AA19: =SUM(W19:Y19) -> -132578.53 | AC19: =SUM(W19:Y19,Q19:S19) -> 382837.24 | AE19: =O19+AC19 -> 8103005.5 | AG19: 842577.63 | AH19: 899941.11 | AI19: 681628.73 | AK19: =SUM(AG19:AI19) -> 2424147.5 | AM19: 798509.8 | AN19: 1208938.5 | AO19: 688128.3 | AQ19: =SUM(AM19:AO19) -> 2695576.6 | AS19: =SUM(AM19:AO19,AG19:AI19) -> 5119724.1 | AU19: 870261.97 | AV19: 547591.59 | AW19: 1107599.6 | AY19: =SUM(AU19:AW19) -> 2525453.2 | BA19: 415303.83 | BB19: 641024.61 | BC19: 1370443.8 | BE19: =SUM(BA19:BC19) -> 2426772.2 | BG19: =SUM(BA19:BC19,AU19:AW19) -> 4952225.4 | BI19: =AS19+BG19 -> 10071949 | BJ19: =SUM(BJ10:BJ18) -> 899440.4 | BK19: =SUM(BK10:BK18) -> 750287.48 | BL19: =SUM(BL10:BL18) -> 799328.24 | BM19: =SUM(BM10:BM18) -> 2107078.8 | BN19: =SUM(BN10:BN18) -> 1990832.8 | BO19: =SUM(BO10:BO18) -> 1930368 | BP19: =SUM(BP10:BP18) -> 1999655.3 | BQ19: =SUM(BQ10:BQ18) -> 2250657.6 | ... BU19: =SUM(BU10:BU18) -> 2104250.5 | BW19: =SUM(BS19:BU19) -> 7346614.3 | BY19: =SUM(BS19:BU19,BP19:BR19) -> 13736479 | CA19: =SUM(CA10:CA18) -> 22213815 | CC19: =SUM(CC10:CC18) -> 1948578.9 | CD19: =SUM(CD10:CD18) -> 1926006.6 | CE19: =SUM(CE10:CE18) -> 3021711.4
B21: Resultado Congl. + Coligadas | C21: -1949518 | D21: 569853.53 | E21: -655977.71 | F21: 8261102.2 | G21: =SUM(D21:F21) -> 8174978.1 | I21: -918167.08 | J21: 1018573 | K21: 2531989.8 | M21: =SUM(I21:K21) -> 2632395.7 | O21: =SUM(I21:K21,D21:F21) -> 10807374 | Q21: 173219.13 | R21: -345764.52 | S21: 5821345.6 | U21: =SUM(Q21:S21) -> 5648800.2 | W21: 2631177.4 | X21: 1917463.3 | Y21: 6352520 | AA21: =SUM(W21:Y21) -> 10901161 | AC21: =SUM(W21:Y21,Q21:S21) -> 16549961 | AE21: =O21+AC21 -> 27357335 | AG21: 916831.05 | AH21: 2129159.7 | AI21: 2080825.3 | AK21: =SUM(AG21:AI21) -> 5126816 | AM21: 2526186 | AN21: 1519360.3 | AO21: 5447326.5 | AQ21: =SUM(AM21:AO21) -> 9492872.7 | AS21: =SUM(AM21:AO21,AG21:AI21) -> 14619689 | AU21: 1941839.3 | AV21: 1817667.9 | AW21: 4568431.6 | AY21: =SUM(AU21:AW21) -> 8327938.8 | BA21: 666753.46 | BB21: 2806903.5 | BC21: 9915384 | BE21: =SUM(BA21:BC21) -> 13389041 | BG21: =SUM(BA21:BC21,AU21:AW21) -> 21716980 | BI21: =AS21+BG21 -> 36336669 | BJ21: =BJ8+BJ19 -> 2007402 | BK21: =BK8+BK19 -> 1106925.1 | BL21: =BL8+BL19 -> 6325716.2 | BM21: =BM8+BM19 -> 6211483.2 | BN21: =BN8+BN19 -> 4257159.5 | BO21: =BO8+BO19 -> 6674743.2 | BP21: =BP8+BP19 -> 4362938.2 | BQ21: =BQ8+BQ19 -> 4217899.8 | ... BU21: =BU8+BU19 -> 6345577.8 | BW21: =SUM(BS21:BU21) -> 15649795 | BY21: =SUM(BS21:BU21,BP21:BR21) -> 29326187 | CA21: =CA19+CA8 -> 55909616 | CC21: =CC8+CC19 -> 3771789.1 | CD21: =CD8+CD19 -> 4309722.3 | CE21: =CE8+CE19 -> 7587055.1
B23: BR Cards | C23: -744679.01 | D23: 2842467.5 | E23: -84774.05 | F23: 1734470.1 | G23: =SUM(D23:F23) -> 4492163.5 | I23: 336223.28 | J23: 424533.92 | K23: 146560.61 | M23: =SUM(I23:K23) -> 907317.81 | O23: =SUM(I23:K23,D23:F23) -> 5399481.3 | Q23: 91429.05 | R23: -137973.28 | S23: -239435.31 | U23: =SUM(Q23:S23) -> -285979.54 | W23: 273119.44 | X23: -431524.45 | Y23: -600734.72 | AA23: =SUM(W23:Y23) -> -759139.73 | AC23: =SUM(W23:Y23,Q23:S23) -> -1045119.3 | AE23: =O23+AC23 -> 4354362 | AG23: 767440.02 | AH23: 750979.9 | AI23: 432757.06 | AK23: =SUM(AG23:AI23) -> 1951177 | AM23: 662524.89 | AN23: 842029.62 | AO23: 593382.21 | AQ23: =SUM(AM23:AO23) -> 2097936.7 | AS23: =SUM(AM23:AO23,AG23:AI23) -> 4049113.7 | AU23: 744180.93 | AV23: 486306.52 | AW23: 1014721.4 | AY23: =SUM(AU23:AW23) -> 2245208.9 | BA23: 214691.41 | BB23: 875982.28 | BC23: 798970.02 | BE23: =SUM(BA23:BC23) -> 1889643.7 | BG23: =SUM(BA23:BC23,AU23:AW23) -> 4134852.6 | BI23: =AS23+BG23 -> 8183966.3 | BJ23: 828965.29 | BK23: 642854.08 | BL23: 537859.73 | BM23: 2092438.7 | BN23: 1856223.5 | BO23: 1915228.4 | BP23: 1829491.1 | BQ23: 2018509.1 | BR23: 2651795.3 | BS23: 2635218.8 | BT23: 1724928.1 | BU23: 1816891.3 | BW23: =SUM(BS23:BU23) -> 6177038.2 | BY23: =SUM(BS23:BU23,BP23:BR23) -> 12676834 | CA23: 21120255 | CC23: 1918146.6 | CD23: 1655619 | CE23: 2648896.4
B24: Resultado MEP | CC24: 1872781.9 | CD24: 1605888.7 | CE24: 2563268.6
B25: Resulta Br Cards | CA25: =CA23-#REF!-#REF! -> #REF! | CC25: 45364.75 | CD25: 49730.27 | CE25: =CE23-CE24 -> 85627.77
B26: RES. TOTAL | C26: =C21+#REF! -> #REF! | D26: =D21+#REF! -> #REF! | E26: =E21+#REF! -> #REF! | F26: =F21+#REF! -> #REF! | G26: =G21+#REF! -> #REF! | I26: =I21+#REF! -> #REF! | J26: =J21+#REF! -> #REF! | K26: =K21+#REF! -> #REF! | M26: =SUM(I26:K26) -> #REF! | O26: =SUM(I26:K26,D26:F26) -> #REF! | Q26: =Q21+#REF! -> #REF! | R26: =R21+#REF! -> #REF! | S26: =S21+#REF! -> #REF! | U26: =SUM(Q26:S26) -> #REF! | W26: =W21+#REF! -> #REF! | X26: =X21+#REF! -> #REF! | Y26: =Y21+#REF! -> #REF! | AA26: =SUM(W26:Y26) -> #REF! | AC26: =SUM(W26:Y26,Q26:S26) -> #REF! | AE26: =AE21+#REF! -> #REF! | AG26: =AG21+#REF! -> #REF! | AH26: =AH21+#REF! -> #REF! | AI26: =AI21+#REF! -> #REF! | AK26: =AK21+#REF! -> #REF! | AM26: =AM21+#REF! -> #REF! | AN26: =AN21+#REF! -> #REF! | AO26: =AO21+#REF! -> #REF! | AQ26: =SUM(AM26:AO26) -> #REF! | AS26: =SUM(AM26:AO26,AG26:AI26) -> #REF! | AU26: =AU21+#REF! -> #REF! | AV26: =AV21+#REF! -> #REF! | AW26: =AW21+#REF! -> #REF! | AY26: =SUM(AU26:AW26) -> #REF! | BA26: =BA21+#REF! -> #REF! | BB26: =BB21+#REF! -> #REF! | BC26: =BC21+#REF! -> #REF! | BE26: =SUM(BA26:BC26) -> #REF! | BG26: =SUM(BA26:BC26,AU26:AW26) -> #REF! | BI26: =BI21+#REF! -> #REF! | BJ26: =BJ21+#REF! -> #REF! | BK26: =BK21+#REF! -> #REF! | BL26: =BL21+#REF! -> #REF! | BM26: =BM21+#REF! -> #REF! | BN26: =BN21+#REF! -> #REF! | BO26: =BO21+#REF! -> #REF! | BP26: =BP21+#REF! -> #REF! | ... BU26: =BU21+#REF! -> #REF! | BW26: =SUM(BS26:BU26) -> #REF! | BY26: =#REF!+BW26 -> #REF! | CA26: =CA21+CA25 -> #REF! | CC26: =CC21+CC25 -> 3817153.8 | CD26: =CD21+CD25 -> 4359452.6 | CE26: =CE21+CE25 -> 7672682.9

Sheet P&L Mensal
B1: Data Base -> | F1: 46112
C3: CONSIGNADO | F3: IMOBILIARIO | I3: TOTAL | N3: IPCA
C4: Realizado | D4: Orçado | E4: ∆ (%) | F4: Realizado | G4: Orçado | H4: ∆ (%) | I4: Realizado | J4: Orçado | K4: ∆ (%) | L4: ∆ (R$) | O4: Realizado | P4: Orçado
B5: RECEITAS | C5: =C6+C13+C15+C16+C17+C18+C14+C19+C20 -> 7877352.9 | D5: =D6+D13+D15+D16+D17+D18+D14+D19+D20 -> 7759392.7 | E5: =IFERROR(C5/D5-1,"-") -> 0.015202255 | F5: =F6+F13+F15+F16+F17+F18+F14+F19+F20 -> 33774613 | G5: =G6+G13+G15+G16+G17+G18+G14+G19+G20 -> 29464374 | H5: =IFERROR(F5/G5-1,"-") -> 0.14628643 | I5: =I6+I13+I15+I16+I17+I18+I14+I19+I20 -> 41651965 | J5: =J6+J13+J15+J16+J17+J18+J14+J19+J20 -> 37223767 | K5: =IFERROR(I5/J5-1,"-") -> 0.11896159 | L5: =I5-J5 -> 4428198.4 | N5: 46023 | O5: 0.0033 | P5: 0.0033
B6: Operações de Crédito | C6: =SUM(C7:C12) -> 7868473.4 | D6: =SUM(D7:D12) -> 7746926.1 | E6: =IFERROR(C6/D6-1,"-") -> 0.015689749 | F6: =SUM(F7:F12) -> 29656161 | G6: =SUM(G7:G12) -> 26280606 | H6: =IFERROR(F6/G6-1,"-") -> 0.12844279 | I6: =C6+F6 -> 37524634 | J6: =D6+G6 -> 34027532 | K6: =IFERROR(I6/J6-1,"-") -> 0.10277271 | L6: =I6-J6 -> 3497101.8 | N6: 46054 | O6: 0.007 | P6: 0.0033
B7: Receita Juros | C7: =INDEX(Realizado!41:41,MATCH('P&L Mensal'!$F$1,Realizado!$2:$2,0))+INDEX(Realizado!42:42,MATCH('P&L Mensal'!$F$1,Realizado!$2:$2,0)) -> 6041460.8 | D7: =INDEX('Orçado '!44:44,MATCH('P&L Mensal'!$F$1,'Orçado '!$2:$2,0))+INDEX('Orçado '!45:45,MATCH('P&L Mensal'!$F$1,'Orçado '!$2:$2,0)) -> 6046154.6 | E7: =IFERROR(C7/D7-1,"-") -> -0.00077634449 | F7: =INDEX(Realizado!83:83,MATCH('P&L Mensal'!$F$1,Realizado!$2:$2,0))+INDEX(Realizado!84:84,MATCH('P&L Mensal'!$F$1,Realizado!$2:$2,0)) -> 21983325 | G7: =INDEX('Orçado '!85:85,MATCH('P&L Mensal'!$F$1,'Orçado '!$2:$2,0))+INDEX('Orçado '!86:86,MATCH('P&L Mensal'!$F$1,'Orçado '!$2:$2,0)) -> 20556772 | H7: =IFERROR(F7/G7-1,"-") -> 0.0693958 | I7: =C7+F7 -> 28024786 | J7: =D7+G7 -> 26602926 | K7: =IFERROR(I7/J7-1,"-") -> 0.053447493 | L7: =I7-J7 -> 1421859.7 | N7: 46082 | O7: 0.0088 | P7: 0.0033
B10: Receita CM - Crédito Imobiliário | C10: =INDEX(Realizado!43:43,MATCH('P&L Mensal'!$F$1,Realizado!$2:$2,0)) -> 0 | D10: =INDEX('Orçado '!46:46,MATCH('P&L Mensal'!$F$1,'Orçado '!$2:$2,0)) -> 0 | E10: =IFERROR(C10/D10-1,"-") -> - | F10: =INDEX(Realizado!85:85,MATCH('P&L Mensal'!$F$1,Realizado!$2:$2,0)) -> 7200722.4 | G10: =INDEX('Orçado '!87:87,MATCH('P&L Mensal'!$F$1,'Orçado '!$2:$2,0)) -> 5309468.9 | H10: =IFERROR(F10/G10-1,"-") -> 0.35620388 | I10: =C10+F10 -> 7200722.4 | J10: =D10+G10 -> 5309468.9 | K10: =IFERROR(I10/J10-1,"-") -> 0.35620388 | L10: =I10-J10 -> 1891253.4
B11: Multa + Mora - Crédito Imobiliário | C11: =INDEX(Realizado!44:44,MATCH('P&L Mensal'!$F$1,Realizado!$2:$2,0)) -> 0 | D11: =INDEX('Orçado '!47:47,MATCH('P&L Mensal'!$F$1,'Orçado '!$2:$2,0)) -> 0 | E11: =IFERROR(C11/D11-1,"-") -> - | F11: =INDEX(Realizado!86:86,MATCH('P&L Mensal'!$F$1,Realizado!$2:$2,0)) -> 394865.93 | G11: =INDEX('Orçado '!88:88,MATCH('P&L Mensal'!$F$1,'Orçado '!$2:$2,0)) -> 372913.43 | H11: =IFERROR(F11/G11-1,"-") -> 0.058867538 | I11: =C11+F11 -> 394865.93 | J11: =D11+G11 -> 372913.43 | K11: =IFERROR(I11/J11-1,"-") -> 0.058867538 | L11: =I11-J11 -> 21952.496
B12: Receita Juros - Cartão | C12: =INDEX(Realizado!45:45,MATCH('P&L Mensal'!$F$1,Realizado!$2:$2,0)) -> 1827012.7 | D12: =INDEX('Orçado '!48:48,MATCH('P&L Mensal'!$F$1,'Orçado '!$2:$2,0)) -> 1700771.4 | E12: =IFERROR(C12/D12-1,"-") -> 0.074225863 | F12: =INDEX(Realizado!87:87,MATCH('P&L Mensal'!$F$1,Realizado!$2:$2,0)) -> 77247.43 | G12: =INDEX('Orçado '!89:89,MATCH('P&L Mensal'!$F$1,'Orçado '!$2:$2,0)) -> 41452.468 | H12: =IFERROR(F12/G12-1,"-") -> 0.86351823 | I12: =C12+F12 -> 1904260.1 | J12: =D12+G12 -> 1742223.9 | K12: =IFERROR(I12/J12-1,"-") -> 0.093005376 | L12: =I12-J12 -> 162036.19
B13: Receita Serviços | C13: =INDEX(Realizado!46:46,MATCH('P&L Mensal'!$F$1,Realizado!$2:$2,0)) -> 0 | D13: =INDEX('Orçado '!49:49,MATCH('P&L Mensal'!$F$1,'Orçado '!$2:$2,0)) -> 0 | E13: =IFERROR(C13/D13-1,"-") -> - | F13: =INDEX(Realizado!88:88,MATCH('P&L Mensal'!$F$1,Realizado!$2:$2,0)) -> 2558364.6 | G13: =INDEX('Orçado '!90:90,MATCH('P&L Mensal'!$F$1,'Orçado '!$2:$2,0)) -> 1754400 | H13: =IFERROR(F13/G13-1,"-") -> 0.45825613 | I13: =C13+F13 -> 2558364.6 | J13: =D13+G13 -> 1754400 | K13: =IFERROR(I13/J13-1,"-") -> 0.45825613 | L13: =I13-J13 -> 803964.56
B14: Receita Interchange | C14: =INDEX(Realizado!47:47,MATCH('P&L Mensal'!$F$1,Realizado!$2:$2,0)) -> 8879.4971 | D14: =INDEX('Orçado '!52:52,MATCH('P&L Mensal'!$F$1,'Orçado '!$2:$2,0)) -> 12466.562 | E14: =IFERROR(C14/D14-1,"-") -> -0.28773487 | F14: =INDEX(Realizado!89:89,MATCH('P&L Mensal'!$F$1,Realizado!$2:$2,0)) -> 11964.393 | G14: =INDEX('Orçado '!93:93,MATCH('P&L Mensal'!$F$1,'Orçado '!$2:$2,0)) -> 16829.858 | H14: =IFERROR(F14/G14-1,"-") -> -0.28909723 | I14: =C14+F14 -> 20843.89 | J14: =D14+G14 -> 29296.42 | K14: =IFERROR(I14/J14-1,"-") -> -0.2885175 | L14: =I14-J14 -> -8452.53
B15: Receita Comissão CRI | C15: =INDEX(Realizado!48:48,MATCH('P&L Mensal'!$F$1,Realizado!$2:$2,0)) -> 0 | D15: =INDEX('Orçado '!53:53,MATCH('P&L Mensal'!$F$1,'Orçado '!$2:$2,0)) -> 0 | E15: =IFERROR(C15/D15-1,"-") -> - | F15: =INDEX(Realizado!90:90,MATCH('P&L Mensal'!$F$1,Realizado!$2:$2,0)) -> 0 | G15: =INDEX('Orçado '!94:94,MATCH('P&L Mensal'!$F$1,'Orçado '!$2:$2,0)) -> 0 | H15: =IFERROR(F15/G15-1,"-") -> - | I15: =C15+F15 -> 0 | J15: =D15+G15 -> 0 | K15: =IFERROR(I15/J15-1,"-") -> - | L15: =I15-J15 -> 0
B16: Receita Cobrança Ext. Cebraco | C16: =INDEX(Realizado!49:49,MATCH('P&L Mensal'!$F$1,Realizado!$2:$2,0)) -> 0 | D16: =INDEX('Orçado '!54:54,MATCH('P&L Mensal'!$F$1,'Orçado '!$2:$2,0)) -> 0 | E16: =IFERROR(C16/D16-1,"-") -> - | F16: =INDEX(Realizado!91:91,MATCH('P&L Mensal'!$F$1,Realizado!$2:$2,0)) -> 155899.01 | G16: =INDEX('Orçado '!95:95,MATCH('P&L Mensal'!$F$1,'Orçado '!$2:$2,0)) -> 282753.77 | H16: =IFERROR(F16/G16-1,"-") -> -0.44864039 | I16: =C16+F16 -> 155899.01 | J16: =D16+G16 -> 282753.77 | K16: =IFERROR(I16/J16-1,"-") -> -0.44864039 | L16: =I16-J16 -> -126854.76
B17: Resultado de Seguros | C17: =INDEX(Realizado!53:53,MATCH('P&L Mensal'!$F$1,Realizado!$2:$2,0)) -> 0 | D17: =INDEX('Orçado '!58:58,MATCH('P&L Mensal'!$F$1,'Orçado '!$2:$2,0)) -> 0 | E17: =IFERROR(C17/D17-1,"-") -> - | F17: =INDEX(Realizado!95:95,MATCH('P&L Mensal'!$F$1,Realizado!$2:$2,0)) -> 1006702.7 | G17: =INDEX('Orçado '!99:99,MATCH('P&L Mensal'!$F$1,'Orçado '!$2:$2,0)) -> 900000 | H17: =IFERROR(F17/G17-1,"-") -> 0.11855856 | I17: =C17+F17 -> 1006702.7 | J17: =D17+G17 -> 900000 | K17: =IFERROR(I17/J17-1,"-") -> 0.11855856 | L17: =I17-J17 -> 106702.7
B18: Resultado Brasil Cards | C18: =INDEX(Realizado!54:54,MATCH('P&L Mensal'!$F$1,Realizado!$2:$2,0)) -> 0 | D18: =INDEX('Orçado '!59:59,MATCH('P&L Mensal'!$F$1,'Orçado '!$2:$2,0)) -> 0 | E18: =IFERROR(C18/D18-1,"-") -> - | F18: =INDEX(Realizado!96:96,MATCH('P&L Mensal'!$F$1,Realizado!$2:$2,0)) -> 126708.72 | G18: =INDEX('Orçado '!100:100,MATCH('P&L Mensal'!$F$1,'Orçado '!$2:$2,0)) -> -163.435 | H18: =IFERROR(F18/G18-1,"-") -> -776.2851 | I18: =C18+F18 -> 126708.72 | J18: =D18+G18 -> -163.435 | K18: =IFERROR(I18/J18-1,"-") -> -776.2851 | L18: =I18-J18 -> 126872.15
B19: Resultado Bari Capital | C19: =INDEX(Realizado!55:55,MATCH('P&L Mensal'!$F$1,Realizado!$2:$2,0)) -> 0 | D19: =INDEX('Orçado '!60:60,MATCH('P&L Mensal'!$F$1,'Orçado '!$2:$2,0)) -> 0 | E19: =IFERROR(C19/D19-1,"-") -> - | F19: =INDEX(Realizado!97:97,MATCH('P&L Mensal'!$F$1,Realizado!$2:$2,0)) -> -262478.75 | G19: =INDEX('Orçado '!101:101,MATCH('P&L Mensal'!$F$1,'Orçado '!$2:$2,0)) -> 19800 | H19: =IFERROR(F19/G19-1,"-") -> -14.256503 | I19: =C19+F19 -> -262478.75 | J19: =D19+G19 -> 19800 | K19: =IFERROR(I19/J19-1,"-") -> -14.256503 | L19: =I19-J19 -> -282278.75
B20: Resultado Sec | C20: 0 | D20: 0 | E20: =IFERROR(C20/D20-1,"-") -> - | F20: =INDEX(Realizado!120:120,MATCH('P&L Mensal'!$F$1,Realizado!$2:$2,0)) -> 521291.11 | G20: =INDEX('Orçado '!102:102,MATCH('P&L Mensal'!$F$1,'Orçado '!$2:$2,0)) -> 210147.87 | H20: =IFERROR(F20/G20-1,"-") -> 1.480592 | I20: =C20+F20 -> 521291.11 | J20: =D20+G20 -> 210147.87 | K20: =IFERROR(I20/J20-1,"-") -> 1.480592 | L20: =I20-J20 -> 311143.24
B21: DESPESAS DE ORIGINAÇÃO | C21: =C22 -> -4803644.1 | D21: =D22 -> -4620516.9 | E21: =IFERROR(C21/D21-1,"-") -> 0.039633491 | F21: =F22 -> -17862654 | G21: =G22 -> -15301310 | H21: =IFERROR(F21/G21-1,"-") -> 0.16739376 | I21: =I22 -> -22666298 | J21: =J22 -> -19921827 | K21: =IFERROR(I21/J21-1,"-") -> 0.13776202 | L21: =ABS(I21)-ABS(J21) -> 2744471.1
B22: Despesa de Captação* | C22: =C23+C26+C27+C28 -> -4803644.1 | D22: =D23+D26+D27+D28 -> -4620516.9 | E22: =IFERROR(C22/D22-1,"-") -> 0.039633491 | F22: =F23+F26+F27+F28 -> -17862654 | G22: =G23+G26+G27+G28 -> -15301310 | H22: =IFERROR(F22/G22-1,"-") -> 0.16739376 | I22: =C22+F22 -> -22666298 | J22: =D22+G22 -> -19921827 | K22: =IFERROR(I22/J22-1,"-") -> 0.13776202 | L22: =ABS(I22)-ABS(J22) -> 2744471.1
B23: Inflação | C23: =INDEX(Realizado!58:58,MATCH('P&L Mensal'!$F$1,Realizado!$2:$2,0)) -> 0 | D23: =INDEX('Orçado '!63:63,MATCH('P&L Mensal'!$F$1,'Orçado '!$2:$2,0)) -> 0 | E23: =IFERROR(C23/D23-1,"-") -> - | F23: =INDEX(Realizado!100:100,MATCH('P&L Mensal'!$F$1,Realizado!$2:$2,0)) -> -6665373.2 | G23: =INDEX('Orçado '!105:105,MATCH('P&L Mensal'!$F$1,'Orçado '!$2:$2,0)) -> -5380522.2 | H23: =IFERROR(F23/G23-1,"-") -> 0.23879672 | I23: =C23+F23 -> -6665373.2 | J23: =D23+G23 -> -5380522.2 | K23: =IFERROR(I23/J23-1,"-") -> 0.23879672 | L23: =ABS(I23)-ABS(J23) -> 1284851
B24: Componente Juros | F24: =INDEX(Realizado!101:101,MATCH('P&L Mensal'!$F$1,Realizado!$2:$2,0)) -> 0 | G24: =INDEX('Orçado '!106:106,MATCH('P&L Mensal'!$F$1,'Orçado '!$2:$2,0)) -> -2734250.7 | I24: =C24+F24 -> 0 | J24: =D24+G24 -> -2734250.7
B25: Componente Inflação | F25: =INDEX(Realizado!102:102,MATCH('P&L Mensal'!$F$1,Realizado!$2:$2,0)) -> 0 | G25: =INDEX('Orçado '!107:107,MATCH('P&L Mensal'!$F$1,'Orçado '!$2:$2,0)) -> -1783873.7 | I25: =C25+F25 -> 0 | J25: =D25+G25 -> -1783873.7
B26: DI/Pré | C26: =INDEX(Realizado!59:59,MATCH('P&L Mensal'!$F$1,Realizado!$2:$2,0)) -> -5760280.5 | D26: =INDEX('Orçado '!64:64,MATCH('P&L Mensal'!$F$1,'Orçado '!$2:$2,0)) -> -5697287.1 | E26: =IFERROR(C26/D26-1,"-") -> 0.011056736 | F26: =INDEX(Realizado!103:103,MATCH('P&L Mensal'!$F$1,Realizado!$2:$2,0)) -> -13440654 | G26: =INDEX('Orçado '!108:108,MATCH('P&L Mensal'!$F$1,'Orçado '!$2:$2,0)) -> -12757576 | H26: =IFERROR(F26/G26-1,"-") -> 0.053542988 | I26: =C26+F26 -> -19200935 | J26: =D26+G26 -> -18454863 | K26: =IFERROR(I26/J26-1,"-") -> 0.040426859 | L26: =ABS(I26)-ABS(J26) -> 746072.13
B27: Receita Financeira + Outros | C27: =+INDEX(Realizado!60:60,MATCH('P&L Mensal'!$F$1,Realizado!$2:$2,0)) -> 683833.18 | D27: =+INDEX('Orçado '!65:65,MATCH('P&L Mensal'!$F$1,'Orçado '!$2:$2,0)) -> 685924.94 | E27: =IFERROR(C27/D27-1,"-") -> -0.0030495583 | F27: =+INDEX(Realizado!104:104,MATCH('P&L Mensal'!$F$1,Realizado!$2:$2,0)) -> 2424498.8 | G27: =+INDEX('Orçado '!109:109,MATCH('P&L Mensal'!$F$1,'Orçado '!$2:$2,0)) -> 2565677.8 | H27: =IFERROR(F27/G27-1,"-") -> -0.055025999 | I27: =C27+F27 -> 3108332 | J27: =D27+G27 -> 3251602.8 | K27: =IFERROR(I27/J27-1,"-") -> -0.044061579 | L27: =ABS(I27)-ABS(J27) -> -143270.75
B28: Swap | C28: =+INDEX(Realizado!61:61,MATCH('P&L Mensal'!$F$1,Realizado!$2:$2,0)) -> 272803.21 | D28: =+INDEX('Orçado '!66:66,MATCH('P&L Mensal'!$F$1,'Orçado '!$2:$2,0)) -> 390845.25 | E28: =IFERROR(C28/D28-1,"-") -> -0.30201734 | F28: =+INDEX(Realizado!105:105,MATCH('P&L Mensal'!$F$1,Realizado!$2:$2,0)) -> -181125.23 | G28: =+INDEX('Orçado '!110:110,MATCH('P&L Mensal'!$F$1,'Orçado '!$2:$2,0)) -> 271109.87 | H28: =IFERROR(F28/G28-1,"-") -> -1.6680879 | I28: =C28+F28 -> 91677.98 | J28: =D28+G28 -> 661955.12 | K28: =IFERROR(I28/J28-1,"-") -> -0.86150424 | L28: =ABS(I28)-ABS(J28) -> -570277.14
B29: Impostos Diretos | C29: =INDEX(Realizado!62:62,MATCH('P&L Mensal'!$F$1,Realizado!$2:$2,0)) -> -220529.89 | D29: =INDEX('Orçado '!67:67,MATCH('P&L Mensal'!$F$1,'Orçado '!$2:$2,0)) -> -169005.8 | E29: =IFERROR(C29/D29-1,"-") -> 0.30486581 | F29: =INDEX(Realizado!106:106,MATCH('P&L Mensal'!$F$1,Realizado!$2:$2,0)) -> -871661.11 | G29: =INDEX('Orçado '!111:111,MATCH('P&L Mensal'!$F$1,'Orçado '!$2:$2,0)) -> -599202.39 | H29: =IFERROR(F29/G29-1,"-") -> 0.45470232 | I29: =C29+F29 -> -1092191 | J29: =D29+G29 -> -768208.19 | K29: =IFERROR(I29/J29-1,"-") -> 0.42173829 | L29: =ABS(I29)-ABS(J29) -> 323982.81
B30: MARGEM INTERMEDIAÇÃO | C30: =C5+C21+C29 -> 2853178.9 | D30: =D5+D21+D29 -> 2969870 | E30: =IFERROR(C30/D30-1,"-") -> -0.039291633 | F30: =F5+F21+F29 -> 15040297 | G30: =G5+G21+G29 -> 13563862 | H30: =IFERROR(F30/G30-1,"-") -> 0.10885068 | I30: =I5+I21+I29 -> 17893476 | J30: =J5+J21+J29 -> 16533732 | K30: =IFERROR(I30/J30-1,"-") -> 0.082240631 | L30: =ABS(I30)-ABS(J30) -> 1359744.5
B31: Provisões | C31: =SUM(C32:C33) -> -610260.52 | D31: =SUM(D32:D33) -> -577819.12 | E31: =IFERROR(C31/D31-1,"-") -> 0.056144559 | F31: =SUM(F32:F33) -> -439697.65 | G31: =SUM(G32:G33) -> -1292046.2 | H31: =IFERROR(F31/G31-1,"-") -> -0.65968892 | I31: =C31+F31 -> -1049958.2 | J31: =D31+G31 -> -1869865.4 | K31: =IFERROR(I31/J31-1,"-") -> -0.43848461 | L31: =ABS(I31)-ABS(J31) -> -819907.19
B32: Provisões | C32: =INDEX(Realizado!65:65,MATCH('P&L Mensal'!$F$1,Realizado!$2:$2,0)) -> -610260.52 | D32: =INDEX('Orçado '!69:69,MATCH('P&L Mensal'!$F$1,'Orçado '!$2:$2,0)) -> -577819.12 | E32: =IFERROR(C32/D32-1,"-") -> 0.056144559 | F32: =INDEX(Realizado!109:109,MATCH('P&L Mensal'!$F$1,Realizado!$2:$2,0)) -> -439697.65 | G32: =INDEX('Orçado '!113:113,MATCH('P&L Mensal'!$F$1,'Orçado '!$2:$2,0)) -> -1292046.2 | H32: =IFERROR(F32/G32-1,"-") -> -0.65968892 | I32: =C32+F32 -> -1049958.2 | J32: =D32+G32 -> -1869865.4 | K32: =IFERROR(I32/J32-1,"-") -> -0.43848461 | L32: =ABS(I32)-ABS(J32) -> -819907.19
B33: Desvalorização de BNDU | C33: =INDEX(Realizado!66:66,MATCH('P&L Mensal'!$F$1,Realizado!$2:$2,0)) -> 0 | D33: 0 | E33: =IFERROR(C33/D33-1,"-") -> - | F33: =INDEX(Realizado!110:110,MATCH('P&L Mensal'!$F$1,Realizado!$2:$2,0)) -> 0 | G33: 0 | H33: =IFERROR(F33/G33-1,"-") -> - | I33: =C33+F33 -> 0 | J33: =D33+G33 -> 0 | K33: =IFERROR(I33/J33-1,"-") -> - | L33: =I33-J33 -> 0
B34: MG INTERMEDIAÇÃO LIQ | C34: =C30+C31 -> 2242918.4 | D34: =D30+D31 -> 2392050.8 | E34: =IFERROR(C34/D34-1,"-") -> -0.062345013 | F34: =F30+F31 -> 14600600 | G34: =G30+G31 -> 12271816 | H34: =IFERROR(F34/G34-1,"-") -> 0.18976688 | I34: =I30+I31 -> 16843518 | J34: =J30+J31 -> 14663866 | K34: =IFERROR(I34/J34-1,"-") -> 0.148641 | L34: =ABS(I34)-ABS(J34) -> 2179651.7
B35: Despesas Administrativas Diretas | C35: =INDEX(Realizado!68:68,MATCH('P&L Mensal'!$F$1,Realizado!$2:$2,0)) -> -466515.01 | D35: =INDEX('Orçado '!71:71,MATCH('P&L Mensal'!$F$1,'Orçado '!$2:$2,0)) -> -486890.14 | E35: =IFERROR(C35/D35-1,"-") -> -0.041847489 | F35: =INDEX(Realizado!112:112,MATCH('P&L Mensal'!$F$1,Realizado!$2:$2,0)) -> -1829214.4 | G35: =INDEX('Orçado '!115:115,MATCH('P&L Mensal'!$F$1,'Orçado '!$2:$2,0)) -> -2394625.7 | H35: =IFERROR(F35/G35-1,"-") -> -0.23611677 | I35: =C35+F35 -> -2295729.4 | J35: =D35+G35 -> -2881515.8 | K35: =IFERROR(I35/J35-1,"-") -> -0.20329106 | L35: =ABS(I35)-ABS(J35) -> -585786.41
B36: Comissão (Apoio - Comercial - Mídia Paga) | C36: =INDEX(Realizado!70:70,MATCH('P&L Mensal'!$F$1,Realizado!$2:$2,0)) -> -40765.595 | D36: =INDEX('Orçado '!72:72,MATCH('P&L Mensal'!$F$1,'Orçado '!$2:$2,0)) -> 0 | E36: =IFERROR(C36/D36-1,"-") -> - | F36: =INDEX(Realizado!114:114,MATCH('P&L Mensal'!$F$1,Realizado!$2:$2,0)) -> -144532.27 | G36: =INDEX('Orçado '!116:116,MATCH('P&L Mensal'!$F$1,'Orçado '!$2:$2,0)) -> -233766.23 | H36: =IFERROR(F36/G36-1,"-") -> -0.38172309 | I36: =C36+F36 -> -185297.86 | J36: =D36+G36 -> -233766.23 | K36: =IFERROR(I36/J36-1,"-") -> -0.20733693 | L36: =ABS(I36)-ABS(J36) -> -48468.374
B37: MG CONTRIBUIÇÃO DIRETA | C37: =C34+C35+C36 -> 1735637.8 | D37: =D34+D35+D36 -> 1905160.7 | E37: =IFERROR(C37/D37-1,"-") -> -0.088980896 | F37: =F34+F35+F36 -> 12626853 | G37: =G34+G35+G36 -> 9643423.6 | H37: =IFERROR(F37/G37-1,"-") -> 0.30937451 | I37: =I34+I35+I36 -> 14362491 | J37: =J34+J35+J36 -> 11548584 | K37: =IFERROR(I37/J37-1,"-") -> 0.24365813 | L37: =ABS(I37)-ABS(J37) -> 2813906.5
B38: Desp. Administrativas Indiretas | C38: =INDEX(Realizado!72:72,MATCH('P&L Mensal'!$F$1,Realizado!$2:$2,0)) -> -533709.79 | D38: =INDEX('Orçado '!74:74,MATCH('P&L Mensal'!$F$1,'Orçado '!$2:$2,0)) -> -575798.96 | E38: =IFERROR(C38/D38-1,"-") -> -0.073096977 | F38: =INDEX(Realizado!116:116,MATCH('P&L Mensal'!$F$1,Realizado!$2:$2,0)) -> -1806616 | G38: =INDEX('Orçado '!118:118,MATCH('P&L Mensal'!$F$1,'Orçado '!$2:$2,0)) -> -2041469 | H38: =IFERROR(F38/G38-1,"-") -> -0.11504117 | I38: =C38+F38 -> -2340325.8 | J38: =D38+G38 -> -2617268 | K38: =IFERROR(I38/J38-1,"-") -> -0.10581345 | L38: =ABS(I38)-ABS(J38) -> -276942.15
B39: Amortização | C39: =+INDEX(Realizado!69:69,MATCH('P&L Mensal'!$F$1,Realizado!$2:$2,0)) -> -93401.924 | D39: =INDEX('Orçado '!75:75,MATCH('P&L Mensal'!$F$1,'Orçado '!$2:$2,0)) -> -88082.166 | E39: =IFERROR(C39/D39-1,"-") -> 0.060395399 | F39: =+INDEX(Realizado!113:113,MATCH('P&L Mensal'!$F$1,Realizado!$2:$2,0)) -> -331152.28 | G39: =INDEX('Orçado '!119:119,MATCH('P&L Mensal'!$F$1,'Orçado '!$2:$2,0)) -> -312291.32 | H39: =IFERROR(F39/G39-1,"-") -> 0.060395399 | I39: =C39+F39 -> -424554.2 | J39: =D39+G39 -> -400373.48 | K39: =IFERROR(I39/J39-1,"-") -> 0.060395399 | L39: =ABS(I39)-ABS(J39) -> 24180.716
B40: RESULTADO ANTES IMPOSTO | C40: =C37+C38+C39 -> 1108526.1 | D40: =D37+D38+D39 -> 1241279.6 | E40: =IFERROR(C40/D40-1,"-") -> -0.10694891 | F40: =F37+F38+F39 -> 10489085 | G40: =G37+G38+G39 -> 7289663.3 | H40: =IFERROR(F40/G40-1,"-") -> 0.43889838 | I40: =I37+I38+I39 -> 11597611 | J40: =J37+J38+J39 -> 8530942.9 | K40: =IFERROR(I40/J40-1,"-") -> 0.35947585 | L40: =ABS(I40)-ABS(J40) -> 3066667.9
B41: Impostos (IR/CSLL) | C41: =INDEX(Realizado!74:74,MATCH('P&L Mensal'!$F$1,Realizado!$2:$2,0)) -> -375153.56 | D41: =INDEX('Orçado '!77:77,MATCH('P&L Mensal'!$F$1,'Orçado '!$2:$2,0)) -> -487969.93 | E41: =IFERROR(C41/D41-1,"-") -> -0.23119534 | F41: =INDEX(Realizado!118:118,MATCH('P&L Mensal'!$F$1,Realizado!$2:$2,0)) -> -3549774.4 | G41: =INDEX('Orçado '!121:121,MATCH('P&L Mensal'!$F$1,'Orçado '!$2:$2,0)) -> -1730075.2 | H41: =IFERROR(F41/G41-1,"-") -> 1.0518035 | I41: =C41+F41 -> -3924927.9 | J41: =D41+G41 -> -2218045.1 | K41: =IFERROR(I41/J41-1,"-") -> 0.76954374 | L41: =I41-J41 -> -1706882.8
B42: RESULTADO CONTÁBIL | C42: =C40+C41 -> 733372.52 | D42: =D40+D41 -> 753309.65 | E42: =IFERROR(C42/D42-1,"-") -> -0.026466044 | F42: =F40+F41 -> 6939310.4 | G42: =G40+G41 -> 5559588.1 | H42: =IFERROR(F42/G42-1,"-") -> 0.24816988 | I42: =I40+I41 -> 7672682.9 | J42: =J40+J41 -> 6312897.7 | K42: =IFERROR(I42/J42-1,"-") -> 0.21539794 | L42: =ABS(I42)-ABS(J42) -> 1359785.2 | N42: Dif: | O42: =RESULTADO!CE26-'P&L Mensal'!I42 -> 0
A43: 2 | B43: RESULTADO ANTES IMPOSTO RECORRENTE | C43: =C40+#REF!+C39-#REF! -> #REF! | D43: =D40+#REF!+D39-#REF! -> #REF! | E43: =IFERROR(C43/D43-1,"-") -> - | F43: =F40+#REF!+F39-#REF! -> #REF! | G43: =G40+#REF!+G39-#REF! -> #REF! | H43: =IFERROR(F43/G43-1,"-") -> - | I43: =C43+F43 -> #REF! | J43: =D43+G43 -> #REF! | K43: =IFERROR(I43/J43-1,"-") -> - | L43: =ABS(I43)-ABS(J43) -> #REF!
...

Sheet Realizado
A2: Consignado | B2: =EOMONTH(C2,-1) -> 44895 | C2: =EOMONTH(D2,-1) -> 44926 | D2: 44957 | E2: =EOMONTH(D2,1) -> 44985 | F2: =EOMONTH(E2,1) -> 45016 | G2: =EOMONTH(F2,1) -> 45046 | H2: =EOMONTH(G2,1) -> 45077 | I2: =EOMONTH(H2,1) -> 45107 | J2: =EOMONTH(I2,1) -> 45138 | K2: =EOMONTH(J2,1) -> 45169 | L2: =EOMONTH(K2,1) -> 45199 | ... AH2: =EOMONTH(AG2,1) -> 45869 | AI2: 45900 | AJ2: 45930 | AK2: =EOMONTH(AJ2,1) -> 45961 | AL2: =EOMONTH(AK2,1) -> 45991 | AM2: =EOMONTH(AL2,1) -> 46022 | AN2: =EOMONTH(AM2,1) -> 46053 | AO2: =EOMONTH(AN2,1) -> 46081 | AP2: =EOMONTH(AO2,1) -> 46112 | AQ2: =EOMONTH(AP2,1) -> 46142 | AR2: =EOMONTH(AQ2,1) -> 46173 | ... AY2: =EOMONTH(AX2,1) -> 46387
A3: RECEITAS
A4: Operações de Crédito
A5: Receita Juros
A6: Receita CM - Crédito Imobiliário
A7: Multa + Mora - Crédito Imobiliário
A8: Receita Juros - Cartão
A9: Receita Serviços
A10: Receita Interchange
A11: Receita Comissão CRI
A12: Receita Cobrança Ext. Cebraco
A13: Barigui Veículos
A14: Honorários
... A38: RESULTADO CONTÁBIL
A39: RECEITAS | AL39: 7704640
A40: Operações de Crédito | AL40: 7667128
A41: Receita Juros | AK41: 5780803.1 | AL41: 5984628.9 | AM41: 6787327.2 | AN41: 6026159.9 | AO41: 5423105.9 | AP41: 6041460.8
A42: Comissão Diferida (TJEO) | AN42: -40115.11
A43: Receita CM - Crédito Imobiliário | AL43: 0
A44: Multa + Mora - Crédito Imobiliário | AL44: 0
A45: Receita Juros - Cartão | AK45: 1785340 | AL45: 1689706.2 | AM45: 1830512.4 | AN45: 1806981.4 | AO45: 1667454.8 | AP45: 1827012.7
A46: Receita Serviços | AL46: 0
A47: Receita Interchange | AL47: 11986.797 | AM47: 12480.275 | AN47: 9001.6569 | AO47: 8163.3698 | AP47: 8879.4971
A48: Receita Comissão CRI | AL48: 0
A49: Receita Cobrança Ext. Cebraco | AL49: 0
A50: Barigui Veículos | AL50: -
A51: Honorários | AL51: -
A52: Securitizadora (Patrimônio Separado) | AL52: -
A53: Resultado de Seguros | AL53: 0
A54: Resultado Brasil Cards | AL54: 0
A55: Resultado Bari Capital | AK55: 0 | AL55: 0 | AM55: 0
A56: DESPESAS DE ORIGINAÇÃO | AL56: -2876490
A57: Despesa de Captação | AL57: -2876490
A58: Inflação | AK58: 0 | AL58: 0
A59: DI/Pré | AK59: =-5871866.4330656-400000 -> -6271866.4 | AL59: -4850067.5 | AM59: =-5329177.64590947-200000 -> -5529177.6 | AN59: =-5284061.23845437+300000 -> -4984061.2 | AO59: -4152791.2 | AP59: -5760280.5
A60: Outros | AK60: =AK124*0.22 -> 525337.89 | AL60: =AL124*0.22 -> 361726.37 | AM60: =AM124*0.22 -> 569799.21 | AN60: =AN124*0.22 -> 533676.18 | AO60: 421756.82 | AP60: 683833.18
A61: Swap | AK61: 721180.7 | AL61: 815785 | AM61: 230403.36 | AN61: 334805.76 | AO61: 272496.22 | AP61: 272803.21
A62: Impostos Diretos | AK62: -158251.41 | AL62: -141845.04 | AM62: 45425.775 | AN62: =-82166.9288-100000 -> -182166.93 | AO62: =-156985.344-(83106.16*0.22) -> -175268.7 | AP62: -220529.89
A63: MARGEM INTERMEDIAÇÃO | AL63: 4626194
A64: Provisões | AL64: -625.627
...

Sheet P&L Acumulado
B1: Data Base -> | F1: De: | G1: 46053 | H1: Até: | I1: 46112 | K1: Proporção anual para Indicadores -> | N1: =12/(MONTH(I1)-MONTH(G1)+1) -> 4
C3: BANCO DIGITAL | F3: CONSIGNADO | I3: IMOBILIARIO | L3: TOTAL
C4: Realizado | D4: Orçado | E4: ∆ (%) | F4: Realizado | G4: Orçado | H4: ∆ (%) | I4: Realizado | J4: Orçado | K4: ∆ (%) | L4: Realizado | M4: Orçado | N4: ∆ (%) | O4: ∆ (R$)
B5: RECEITAS | C5: =C6+C12+C14+C15+C20+C21+C13 -> 0 | D5: =D6+D12+D14+D15+D20+D21+D13 -> 0 | E5: =IFERROR(C5/D5-1,"-") -> - | F5: =F6+F12+F14+F15+F20+F21+F13+F22+F23 -> 22778105 | G5: =G6+G12+G14+G15+G20+G21+G13+G22+G23 -> 22452623 | H5: =IFERROR(F5/G5-1,"-") -> 0.014496375 | I5: =I6+I12+I14+I15+I20+I21+I13+I22+I23 -> 81408364 | J5: =J6+J12+J14+J15+J20+J21+J13+J22+J23 -> 77414896 | K5: =IFERROR(I5/J5-1,"-") -> 0.05158527 | L5: =L6+L12+L14+L15+L20+L21+L13+L22+L23 -> 1.0418647e+08 | M5: =M6+M12+M14+M15+M20+M21+M13+M22+M23 -> 99867519 | N5: =IFERROR(L5/M5-1,"-") -> 0.043246794 | O5: =L5-M5 -> 4318950
B6: Operações de Crédito | C6: =IFERROR(SUMIFS(Realizado!4:4,Realizado!$2:$2,">="&'P&L Acumulado'!$G$1,Realizado!$2:$2,"<="&'P&L Acumulado'!$I$1),0) -> 0 | D6: =IFERROR(SUMIFS('Orçado '!4:4,'Orçado '!$2:$2,">="&'P&L Acumulado'!$G$1,Realizado!$2:$2,"<="&'P&L Acumulado'!$I$1),0) -> 0 | E6: =IFERROR(C6/D6-1,"-") -> - | F6: =SUM(F7:F11) -> 22752060 | G6: =SUM(G7:G11) -> 22415224 | H6: =IFERROR(F6/G6-1,"-") -> 0.015027145 | I6: =SUM(I7:I11) -> 71830315 | J6: =SUM(J7:J11) -> 67855802 | K6: =IFERROR(I6/J6-1,"-") -> 0.058572932 | L6: =C6+F6+I6 -> 94582375 | M6: =D6+G6+J6 -> 90271025 | N6: =IFERROR(L6/M6-1,"-") -> 0.047760065 | O6: =L6-M6 -> 4311350.1
B7: Receita Juros | C7: =IFERROR(SUMIFS(Realizado!5:5,Realizado!$2:$2,">="&'P&L Acumulado'!$G$1,Realizado!$2:$2,"<="&'P&L Acumulado'!$I$1),0) -> 0 | D7: =IFERROR(SUMIFS('Orçado '!5:5,'Orçado '!$2:$2,">="&'P&L Acumulado'!$G$1,Realizado!$2:$2,"<="&'P&L Acumulado'!$I$1),0) -> 0 | E7: =IFERROR(C7/D7-1,"-") -> - | F7: =IFERROR(SUMIFS(Realizado!41:41,Realizado!$2:$2,">="&'P&L Acumulado'!$G$1,Realizado!$2:$2,"<="&'P&L Acumulado'!$I$1),0)+IFERROR(SUMIFS(Realizado!42:42,Realizado!$2:$2,">="&'P&L Acumulado'!$G$1,Realizado!$2:$2,"<="&'P&L Acumulado'!$I$1),0) -> 17450611 | G7: =IFERROR(SUMIFS('Orçado '!43:43,'Orçado '!$2:$2,">="&'P&L Acumulado'!$G$1,Realizado!$2:$2,"<="&'P&L Acumulado'!$I$1),0) -> 17438113 | H7: =IFERROR(F7/G7-1,"-") -> 0.00071675226 | I7: =IFERROR(SUMIFS(Realizado!83:83,Realizado!$2:$2,">="&'P&L Acumulado'!$G$1,Realizado!$2:$2,"<="&'P&L Acumulado'!$I$1),0)++IFERROR(SUMIFS(Realizado!84:84,Realizado!$2:$2,">="&'P&L Acumulado'!$G$1,Realizado!$2:$2,"<="&'P&L Acumulado'!$I$1),0) -> 56795931 | J7: =IFERROR(SUMIFS('Orçado '!84:84,'Orçado '!$2:$2,">="&'P&L Acumulado'!$G$1,Realizado!$2:$2,"<="&'P&L Acumulado'!$I$1),0) -> 54892046 | K7: =IFERROR(I7/J7-1,"-") -> 0.034684157 | L7: =C7+F7+I7 -> 74246542 | M7: =D7+G7+J7 -> 72330159 | N7: =IFERROR(L7/M7-1,"-") -> 0.026494939 | O7: =L7-M7 -> 1916383.2
B8: Receita CM - Crédito Imobiliário | C8: =IFERROR(SUMIFS(Realizado!6:6,Realizado!$2:$2,">="&'P&L Acumulado'!$G$1,Realizado!$2:$2,"<="&'P&L Acumulado'!$I$1),0) -> 0 | D8: =IFERROR(SUMIFS('Orçado '!6:6,'Orçado '!$2:$2,">="&'P&L Acumulado'!$G$1,Realizado!$2:$2,"<="&'P&L Acumulado'!$I$1),0) -> 0 | E8: =IFERROR(C8/D8-1,"-") -> - | F8: =IFERROR(SUMIFS(Realizado!43:43,Realizado!$2:$2,">="&'P&L Acumulado'!$G$1,Realizado!$2:$2,"<="&'P&L Acumulado'!$I$1),0) -> 0 | G8: =IFERROR(SUMIFS('Orçado '!46:46,'Orçado '!$2:$2,">="&'P&L Acumulado'!$G$1,Realizado!$2:$2,"<="&'P&L Acumulado'!$I$1),0) -> 0 | H8: =IFERROR(F8/G8-1,"-") -> - | I8: =IFERROR(SUMIFS(Realizado!85:85,Realizado!$2:$2,">="&'P&L Acumulado'!$G$1,Realizado!$2:$2,"<="&'P&L Acumulado'!$I$1),0) -> 13818700 | J8: =IFERROR(SUMIFS('Orçado '!87:87,'Orçado '!$2:$2,">="&'P&L Acumulado'!$G$1,Realizado!$2:$2,"<="&'P&L Acumulado'!$I$1),0) -> 11742056 | K8: =IFERROR(I8/J8-1,"-") -> 0.1768552 | L8: =C8+F8+I8 -> 13818700 | M8: =D8+G8+J8 -> 11742056 | N8: =IFERROR(L8/M8-1,"-") -> 0.1768552 | O8: =L8-M8 -> 2076643.7
